Workbook

Sheet Sheet1
A1: Cross Validation Outliers
B3: year_position_raw | C3: mean_surprisal | D3: Genre (Broad 1) | F3: Song Title | G3: Artist
A4: 483 | B4: 1962_01_1 | C4: 7.569407 | D4: Jazz | E4: =_xlfn.TEXTBEFORE(B4,"_",2) -> 1962_01 | F4: =INDEX(bimmuda_per_song_metadata!A:A,MATCH($E4,bimmuda_per_song_metadata!$AB:$AB,1),1) -> Stranger on the Shore | G4: =INDEX(bimmuda_per_song_metadata!B:B,MATCH($E4,bimmuda_per_song_metadata!$AB:$AB,1),1) -> Acker Bilk
A5: 748 | B5: 1993_04_1 | C5: 7.566777 | D5: R&B | E5: =_xlfn.TEXTBEFORE(B5,"_",2) -> 1993_04 | F5: =INDEX(bimmuda_per_song_metadata!A:A,MATCH($E5,bimmuda_per_song_metadata!$AB:$AB,1),1) -> That's the Way Love Goes | G5: =INDEX(bimmuda_per_song_metadata!B:B,MATCH($E5,bimmuda_per_song_metadata!$AB:$AB,1),1) -> Janet Jackson
A6: 671 | B6: 1956_04_3 | C6: 7.248999 | D6: R&B | E6: =_xlfn.TEXTBEFORE(B6,"_",2) -> 1956_04 | F6: =INDEX(bimmuda_per_song_metadata!A:A,MATCH($E6,bimmuda_per_song_metadata!$AB:$AB,1),1) -> My Prayer | G6: =INDEX(bimmuda_per_song_metadata!B:B,MATCH($E6,bimmuda_per_song_metadata!$AB:$AB,1),1) -> The Platters
B8: year_position_raw | C8: mean_surprisal | D8: Genre (Broad 1)
A9: 362 | B9: 2013_04_4 | C9: 0.8229 | D9: EDM/Dance | E9: =_xlfn.TEXTBEFORE(B9,"_",2) -> 2013_04 | F9: =INDEX(bimmuda_per_song_metadata!A:A,MATCH($E9,bimmuda_per_song_metadata!$AB:$AB,1),1) -> Harlem Shake | G9: =INDEX(bimmuda_per_song_metadata!B:B,MATCH($E9,bimmuda_per_song_metadata!$AB:$AB,1),1) -> Baauer
A10: 167 | B10: 2013_04_5 | C10: 1.279061 | D10: EDM/Dance | E10: =_xlfn.TEXTBEFORE(B10,"_",2) -> 2013_04 | F10: =INDEX(bimmuda_per_song_metadata!A:A,MATCH($E10,bimmuda_per_song_metadata!$AB:$AB,1),1) -> Harlem Shake | G10: =INDEX(bimmuda_per_song_metadata!B:B,MATCH($E10,bimmuda_per_song_metadata!$AB:$AB,1),1) -> Baauer
A11: 486 | B11: 2003_01_1 | C11: 1.327483 | D11: Hip-hop | E11: =_xlfn.TEXTBEFORE(B11,"_",2) -> 2003_01 | F11: =INDEX(bimmuda_per_song_metadata!A:A,MATCH($E11,bimmuda_per_song_metadata!$AB:$AB,1),1) -> In da Club | G11: =INDEX(bimmuda_per_song_metadata!B:B,MATCH($E11,bimmuda_per_song_metadata!$AB:$AB,1),1) -> 50 Cent
A14: 5 Yr Lookback Outliers
B16: song | C16: mean_surprisal | D16: Genre (Broad 1)
A17: 4481 | B17: 2014_02_misc | C17: 40.064836 | D17: Hip-hop | E17: =_xlfn.TEXTBEFORE(B17,"_",2) -> 2014_02 | F17: =INDEX(bimmuda_per_song_metadata!A:A,MATCH($E17,bimmuda_per_song_metadata!$AB:$AB,1),1) -> Dark Horse | G17: =INDEX(bimmuda_per_song_metadata!B:B,MATCH($E17,bimmuda_per_song_metadata!$AB:$AB,1),1) -> Katy Perry and Juicy J
A18: 1296 | B18: 1974_03_1 | C18: 36.879334 | D18: Funk/Soul | E18: =_xlfn.TEXTBEFORE(B18,"_",2) -> 1974_03 | F18: =INDEX(bimmuda_per_song_metadata!A:A,MATCH($E18,bimmuda_per_song_metadata!$AB:$AB,1),1) -> Love's Theme | G18: =INDEX(bimmuda_per_song_metadata!B:B,MATCH($E18,bimmuda_per_song_metadata!$AB:$AB,1),1) -> Love Unlimited Orchestra
A19: 885 | B19: 1968_02_2 | C19: 29.0582 | D19: Pop | E19: =_xlfn.TEXTBEFORE(B19,"_",2) -> 1968_02 | F19: =INDEX(bimmuda_per_song_metadata!A:A,MATCH($E19,bimmuda_per_song_metadata!$AB:$AB,1),1) -> Love is Blue | G19: =INDEX(bimmuda_per_song_metadata!B:B,MATCH($E19,bimmuda_per_song_metadata!$AB:$AB,1),1) -> Paul Mauriat
A21: 4651 | B21: 2013_04_4 | C21: 0.587108 | D21: EDM/Dance | E21: =_xlfn.TEXTBEFORE(B21,"_",2) -> 2013_04 | F21: =INDEX(bimmuda_per_song_metadata!A:A,MATCH($E21,bimmuda_per_song_metadata!$AB:$AB,1),1) -> Harlem Shake | G21: =INDEX(bimmuda_per_song_metadata!B:B,MATCH($E21,bimmuda_per_song_metadata!$AB:$AB,1),1) -> Baauer
A22: 4561 | B22: 2013_04_4 | C22: 0.588805 | D22: EDM/Dance | E22: =_xlfn.TEXTBEFORE(B22,"_",2) -> 2013_04 | F22: =INDEX(bimmuda_per_song_metadata!A:A,MATCH($E22,bimmuda_per_song_metadata!$AB:$AB,1),1) -> Harlem Shake | G22: =INDEX(bimmuda_per_song_metadata!B:B,MATCH($E22,bimmuda_per_song_metadata!$AB:$AB,1),1) -> Baauer
A23: 4735 | B23: 2013_04_4 | C23: 0.596173 | D23: EDM/Dance | E23: =_xlfn.TEXTBEFORE(B23,"_",2) -> 2013_04 | F23: =INDEX(bimmuda_per_song_metadata!A:A,MATCH($E23,bimmuda_per_song_metadata!$AB:$AB,1),1) -> Harlem Shake | G23: =INDEX(bimmuda_per_song_metadata!B:B,MATCH($E23,bimmuda_per_song_metadata!$AB:$AB,1),1) -> Baauer
A26: 10 Yr Lookback Outliers
B28: song | C28: mean_surprisal | D28: Genre (Broad 1)
A29: 271 | B29: 1979_01_3 | C29: 13.26312 | D29: Rock | E29: =_xlfn.TEXTBEFORE(B29,"_",2) -> 1979_01 | F29: =INDEX(bimmuda_per_song_metadata!A:A,MATCH($E29,bimmuda_per_song_metadata!$AB:$AB,1),1) -> My Sharona | G29: =INDEX(bimmuda_per_song_metadata!B:B,MATCH($E29,bimmuda_per_song_metadata!$AB:$AB,1),1) -> The Knack
A30: 118 | B30: 1969_02_2 | C30: 9.516567 | D30: Funk/Soul | E30: =_xlfn.TEXTBEFORE(B30,"_",2) -> 1969_02 | F30: =INDEX(bimmuda_per_song_metadata!A:A,MATCH($E30,bimmuda_per_song_metadata!$AB:$AB,1),1) -> Aquarius/Let the Sunshine In (The Flesh Failures) | G30: =INDEX(bimmuda_per_song_metadata!B:B,MATCH($E30,bimmuda_per_song_metadata!$AB:$AB,1),1) -> The 5th Dimension
A31: 285 | B31: 1980_01_2 | C31: 8.963967 | D31: Rock | E31: =_xlfn.TEXTBEFORE(B31,"_",2) -> 1980_01 | F31: =INDEX(bimmuda_per_song_metadata!A:A,MATCH($E31,bimmuda_per_song_metadata!$AB:$AB,1),1) -> Call Me | G31: =INDEX(bimmuda_per_song_metadata!B:B,MATCH($E31,bimmuda_per_song_metadata!$AB:$AB,1),1) -> Blondie
A33: song mean_surprisal Genre (Broad 1) _1 1.499772 Hip-hop
A34: 821 | B34: 2013_04_4 | C34: 0.846795 | D34: EDM/Dance | E34: =_xlfn.TEXTBEFORE(B34,"_",2) -> 2013_04 | F34: =INDEX(bimmuda_per_song_metadata!A:A,MATCH($E34,bimmuda_per_song_metadata!$AB:$AB,1),1) -> Harlem Shake | G34: =INDEX(bimmuda_per_song_metadata!B:B,MATCH($E34,bimmuda_per_song_metadata!$AB:$AB,1),1) -> Baauer
A35: 822 | B35: 2013_04_5 | C35: 1.29019 | D35: EDM/Dance | E35: =_xlfn.TEXTBEFORE(B35,"_",2) -> 2013_04 | F35: =INDEX(bimmuda_per_song_metadata!A:A,MATCH($E35,bimmuda_per_song_metadata!$AB:$AB,1),1) -> Harlem Shake | G35: =INDEX(bimmuda_per_song_metadata!B:B,MATCH($E35,bimmuda_per_song_metadata!$AB:$AB,1),1) -> Baauer
A36: 648 | B36: 2003_01_1 | C36: 1.499772 | D36: Hip-hop | E36: =_xlfn.TEXTBEFORE(B36,"_",2) -> 2003_01 | F36: =INDEX(bimmuda_per_song_metadata!A:A,MATCH($E36,bimmuda_per_song_metadata!$AB:$AB,1),1) -> In da Club | G36: =INDEX(bimmuda_per_song_metadata!B:B,MATCH($E36,bimmuda_per_song_metadata!$AB:$AB,1),1) -> 50 Cent

Sheet bimmuda_per_song_metadata
A1: Title | B1: Artist | C1: Year | D1: Position | E1: Genre (Broad 1) | F1: Genre (Broad 2) | G1: Genre (Specific 1) | H1: Genre (Specific 2) | I1: Genre (Specific 3) | J1: Link to Audio | K1: Time Signature 1 | L1: Time Signature 2 | M1: Tonic 1 | N1: Tonic 2 | O1: Tonic 3 | P1: Tonic 4 | Q1: Tonic 5 | R1: Tonic 6 | S1: Mode 1 | T1: Mode 2 | U1: Mode 3 | V1: Mode 4 | W1: Mode 5 | X1: Mode 6 | Y1: BPM 1 | Z1: BPM 2 | AA1: BPM 3 | AB1: year_position
A2: Goodnight Irene | B2: Gordon Jenkins & The Weavers | C2: 1950 | D2: 1 | E2: Folk | F2: N/A | G2: N/A | H2: N/A | I2: N/A | J2: https://open.spotify.com/track/3GtfeLBXe15nyEMN664ygs?si=39b24fc00f4f4cf5 | K2: 46085 | M2: F | S2: Major | Y2: 94 | Z2: 141 | AB2: =C2&"_"&TEXT(D2,"0#") -> 1950_01
A3: Mona Lisa | B3: Nat King Cole | C3: 1950 | D3: 2 | E3: Pop | F3: N/A | G3: Traditional pop | H3: N/A | I3: N/A | J3: https://open.spotify.com/track/5dae01pKNjRQtgOeAkFzPY?si=15779469d4874d3d | K3: 46116 | M3: Db | S3: Major | Y3: 65 | AB3: =C3&"_"&TEXT(D3,"0#") -> 1950_02
A4: Third Man Theme | B4: Anton Karas | C4: 1950 | D4: 3 | E4: Folk | F4: N/A | G4: N/A | H4: N/A | I4: N/A | J4: https://open.spotify.com/track/7rRGujA12UJcRUz7DxUDwQ?si=a206215c97394f61 | K4: 46364 | M4: F# | S4: Major | Y4: 176 | Z4: 152 | AB4: =C4&"_"&TEXT(D4,"0#") -> 1950_03
A5: Sam's Song | B5: Gary & Bing Crosby | C5: 1950 | D5: 4 | E5: Pop | F5: N/A | G5: Traditional pop | H5: N/A | I5: N/A | J5: https://open.spotify.com/track/1Wnlagmoyo7M7Ine1wY71p?si=31b7831d43224031 | K5: 46364 | M5: Eb | S5: Major | Y5: 118 | AB5: =C5&"_"&TEXT(D5,"0#") -> 1950_04
A6: Simple Melody | B6: Gary & Bing Crosby | C6: 1950 | D6: 5 | E6: Pop | F6: N/A | G6: Traditional pop | H6: N/A | I6: N/A | J6: https://open.spotify.com/track/75lpxrV9sLZIRvzl2Z5CBb?si=b072ddb2bca34acb | K6: 46364 | M6: Bb | S6: Major | Y6: 151 | AB6: =C6&"_"&TEXT(D6,"0#") -> 1950_05
A7: Too Young | B7: Nat King Cole | C7: 1951 | D7: 1 | E7: Pop | F7: N/A | G7: Traditional pop | H7: N/A | I7: N/A | J7: https://open.spotify.com/track/0zII0Soax7wbm3Avw7iVAd?si=fd982113338544af | K7: 46116 | M7: Ab | S7: Major | Y7: 96 | AB7: =C7&"_"&TEXT(D7,"0#") -> 1951_01
A8: Because of You | B8: Tony Bennett | C8: 1951 | D8: 2 | E8: Pop | F8: N/A | G8: Traditional pop | H8: N/A | I8: N/A | J8: https://open.spotify.com/track/4DTO96EvOW9JT6OIUNFpZW?si=1bb52069ae4240de | K8: 46116 | M8: F# | S8: Major | Y8: 84 | AB8: =C8&"_"&TEXT(D8,"0#") -> 1951_02
A9: How High the Moon | B9: Les Paul & Mary Ford | C9: 1951 | D9: 3 | E9: Pop | F9: Jazz | G9: N/A | H9: N/A | I9: N/A | J9: https://open.spotify.com/track/0onHzLoj8yQbjbHtJzwjBx?si=94f73acf642e45b2 | K9: 46116 | M9: A | S9: Major | Y9: 119 | AB9: =C9&"_"&TEXT(D9,"0#") -> 1951_03
A10: Come on-a My House | B10: Rosemary Clooney | C10: 1951 | D10: 4 | E10: Pop | F10: N/A | G10: Traditional pop | H10: N/A | I10: N/A | J10: https://open.spotify.com/track/3GVyT9fBXuEkGs1STo2WHZ?si=be400ee0309f411d | K10: 46364 | M10: Bb | S10: Minor | Y10: 184 | AB10: =C10&"_"&TEXT(D10,"0#") -> 1951_04
A11: Be My Love | B11: Mario Lanza | C11: 1951 | D11: 5 | E11: Pop | F11: N/A | G11: Traditional pop | H11: N/A | I11: N/A | J11: https://open.spotify.com/track/7bETs6oajlWYVo9ycX74Vp?si=4dedbb8fdc8543a1 | K11: 46116 | M11: Db | N11: C | S11: Major | T11: Major | Y11: 87 | AB11: =C11&"_"&TEXT(D11,"0#") -> 1951_05
A12: Blue Tango | B12: Leroy Anderson | C12: 1952 | D12: 1 | E12: Pop | F12: N/A | G12: Easy listening | H12: N/A | I12: N/A | J12: https://open.spotify.com/track/6ecG5Am0TRxn0uwZBQHA3L?si=dc69c7a9494c448f | K12: 46116 | M12: D | S12: Major | Y12: 124 | AB12: =C12&"_"&TEXT(D12,"0#") -> 1952_01
A13: Wheel of Fortune | B13: Kay Starr | C13: 1952 | D13: 2 | E13: Pop | F13: N/A | G13: Traditional pop | H13: N/A | I13: N/A | J13: https://open.spotify.com/track/2gCQe48O4GMJz6oFBqnN9e?si=8a25159095894402 | K13: 46116 | M13: Ab | S13: Major | Y13: 141 | AB13: =C13&"_"&TEXT(D13,"0#") -> 1952_02
A14: Cry | B14: Johnnie Ray & The Four Lads | C14: 1952 | D14: 3 | E14: Pop | F14: N/A | G14: Traditional pop | H14: N/A | I14: N/A | J14: https://open.spotify.com/track/6I3CrqLrSqSlGzs2dactg1?si=8b07a850c7f44fd9 | K14: 46116 | M14: C | S14: Major | Y14: 70 | AB14: =C14&"_"&TEXT(D14,"0#") -> 1952_03
A15: You Belong to Me | B15: Jo Stafford | C15: 1952 | D15: 4 | E15: Pop | F15: N/A | G15: Traditional pop | H15: N/A | I15: N/A | J15: https://open.spotify.com/track/2NDMLabAjx4oL7ezx2PNxS?si=e3ecc4e898c54ee5 | K15: 46364 | M15: F | S15: Major | Y15: 102 | AB15: =C15&"_"&TEXT(D15,"0#") -> 1952_04
A16: Auf Wiederseh‚Äôn Sweetheart | B16: Vera Lynn | C16: 1952 | D16: 5 | E16: Pop | F16: N/A | G16: Traditional pop | H16: N/A | I16: N/A | J16: https://open.spotify.com/track/3MXrq618qP3RGWs6F49U1Q?si=6b54e73f40b14e59 | K16: 46116 | M16: Ab | S16: Major | Y16: 108 | AB16: =C16&"_"&TEXT(D16,"0#") -> 1952_05
A17: The Song from Moulin Rouge | B17: Percy Faith | C17: 1953 | D17: 1 | E17: Pop | F17: N/A | G17: Traditional pop | H17: Easy listening | I17: N/A | J17: https://open.spotify.com/track/7GtpZ01gEJDxrXfH2ayvuc?si=129bfeb7a2d44eb7 | K17: 46085 | M17: G | N17: C | O17: E | P17: A | S17: Major | T17: Major | U17: Major | V17: Major | Y17: 72 | AB17: =C17&"_"&TEXT(D17,"0#") -> 1953_01
A18: Vaya con Dios | B18: Les Paul & Mary Ford | C18: 1953 | D18: 2 | E18: Pop | F18: N/A | G18: Traditional pop | H18: N/A | I18: N/A | J18: https://open.spotify.com/track/3qhxI5f7klTVfK0iWYmKdM?si=9a0fb72b0ba6455f | K18: 46273 | M18: E | S18: Major | Y18: 97 | AB18: =C18&"_"&TEXT(D18,"0#") -> 1953_02
A19: (How Much Is) That Doggie in the Window | B19: Patti Page | C19: 1953 | D19: 3 | E19: Pop | F19: N/A | G19: Traditional pop | H19: N/A | I19: N/A | J19: https://open.spotify.com/track/7bs4wDnaX0z7BTeM6lTcYA?si=86fdd28b03b34d1d | K19: 46085 | M19: G | N19: Ab | O19: A | S19: Major | T19: Major | U19: Major | Y19: 126 | AB19: =C19&"_"&TEXT(D19,"0#") -> 1953_03
A20: I'm Walking Behind You | B20: Eddie Fisher | C20: 1953 | D20: 4 | E20: Pop | F20: N/A | G20: Traditional pop | H20: N/A | I20: N/A | J20: https://open.spotify.com/track/2FqOLG4ViICqhx35v8xoBx?si=2f6b67fc2dc14577 | K20: 46116 | M20: D | S20: Major | Y20: 83 | AB20: =C20&"_"&TEXT(D20,"0#") -> 1953_04
A21: You, You, You | B21: Ames Brothers | C21: 1953 | D21: 5 | E21: Pop | F21: N/A | G21: Traditional pop | H21: Easy listening | I21: N/A | J21: https://open.spotify.com/track/7fvf369TehoRNdWWUfPSqQ?si=19821cc9669b461f | K21: 46364 | M21: E | S21: Major | Y21: 98 | AB21: =C21&"_"&TEXT(D21,"0#") -> 1953_05
A22: Little Things Mean a Lot | B22: Kitty Kallen | C22: 1954 | D22: 1 | E22: Pop | F22: N/A | G22: Traditional pop | H22: N/A | I22: N/A | J22: https://open.spotify.com/track/6rJZdaRiIysWoWoNoxCjZo?si=b8408d5023334ad3 | K22: 46364 | M22: Ab | S22: Major | Y22: 84 | AB22: =C22&"_"&TEXT(D22,"0#") -> 1954_01
A23: Wanted | B23: Perry Como | C23: 1954 | D23: 2 | E23: Pop | F23: N/A | G23: N/A | H23: N/A | I23: N/A | J23: https://open.spotify.com/track/77i95B3GcC2aOqK70RHM0m?si=0b98923e55074997 | K23: 46364 | M23: Db | S23: Minor | Y23: 75 | AB23: =C23&"_"&TEXT(D23,"0#") -> 1954_02
A24: Hey There | B24: Rosemary Clooney | C24: 1954 | D24: 3 | E24: Pop | F24: N/A | G24: Traditional pop | H24: N/A | I24: N/A | J24: https://open.spotify.com/track/0hNwfLcROljm0Wk9zWIQ6z?si=db1ba0af3a204281 | K24: 46116 | M24: G | S24: Minor | Y24: 88 | AB24: =C24&"_"&TEXT(D24,"0#") -> 1954_03
A25: Sh-Boom | B25: The Crew-Cuts | C25: 1954 | D25: 4 | E25: R&B | F25: Pop | G25: Doo-wop | H25: Traditional pop | I25: N/A | J25: https://open.spotify.com/track/7G2jAmiYUDZKyk7npVrgX8?si=3976dd4a758b4b45 | K25: 46364 | M25: F | S25: Major | Y25: 130 | AB25: =C25&"_"&TEXT(D25,"0#") -> 1954_04
A26: Make Love to Me | B26: Jo Stafford | C26: 1954 | D26: 5 | E26: Pop | F26: N/A | G26: N/A | H26: N/A | I26: N/A | J26: https://www.youtube.com/watch?v=JG5Brc9KrS8 | K26: 46364 | M26: A | S26: Major | Y26: 108 | AB26: =C26&"_"&TEXT(D26,"0#") -> 1954_05
A27: Cherry Pink and Apple Blossom White | B27: Perez Prado | C27: 1955 | D27: 1 | E27: Latin | F27: N/A | G27: N/A | H27: N/A | I27: N/A | J27: https://open.spotify.com/track/5HisVcYPaIB4uHdrnW6HCt?si=ec6a72e747534fb9 | K27: 46116 | M27: Eb | S27: Major | Y27: 118 | AB27: =C27&"_"&TEXT(D27,"0#") -> 1955_01
A28: Rock Around the Clock | B28: Bill Haley & His Comets | C28: 1955 | D28: 2 | E28: Rock | F28: N/A | G28: Rockabilly | H28: N/A | I28: N/A | J28: https://open.spotify.com/track/7hLOIb9E7VKmsVelNq6YZK?si=ad896ef8e3c14fa1 | K28: 46116 | M28: A | S28: Major | Y28: 182 | AB28: =C28&"_"&TEXT(D28,"0#") -> 1955_02
A29: The Yellow Rose of Texas | B29: Mitch Miller | C29: 1955 | D29: 3 | E29: Folk | F29: N/A | G29: N/A | H29: N/A | I29: N/A | J29: https://open.spotify.com/track/7985fUI9WlsIIrQuO9TBDh?si=292e16947965486c | K29: 46116 | M29: Ab | N29: A | O29: Bb | S29: Major | T29: Major | U29: Major | Y29: 100 | AB29: =C29&"_"&TEXT(D29,"0#") -> 1955_03
A30: Autumn Leaves | B30: Roger Williams | C30: 1955 | D30: 4 | E30: Jazz | F30: N/A | G30: N/A | H30: N/A | I30: N/A | J30: https://open.spotify.com/track/3hg2zWOJ0MCgvBCD8fzMgt?si=87f37a74bf06472c | K30: 46116 | M30: D | S30: Minor | Y30: 112 | AB30: =C30&"_"&TEXT(D30,"0#") -> 1955_04
A31: Unchained Melody | B31: Les Baxter | C31: 1955 | D31: 5 | E31: Pop | F31: N/A | G31: Easy listening | H31: N/A | I31: N/A | J31: https://open.spotify.com/track/4dnbvB2Y3cZncApCwowEQx?si=e0bb4996368645dc | K31: 46116 | M31: G | S31: Major | Y31: 93 | Z31: 70 | AB31: =C31&"_"&TEXT(D31,"0#") -> 1955_05
A32: Heartbreak Hotel | B32: Elvis Presley | C32: 1956 | D32: 1 | E32: Rock | F32: R&B | G32: Rockabilly | H32: N/A | I32: N/A | J32: https://open.spotify.com/track/6xNwKNYZcvgV3XTIwsgNio?si=064429528c474207 | K32: 46364 | M32: E | S32: Minor | Y32: 94 | AB32: =C32&"_"&TEXT(D32,"0#") -> 1956_01
A33: Don't Be Cruel | B33: Elvis Presley | C33: 1956 | D33: 2 | E33: Rock | F33: N/A | G33: Rockabilly | H33: N/A | I33: N/A | J33: https://open.spotify.com/track/01u6AEzGbGbQyYVdxajxqk?si=c4f1fe5c7e0e4487 | K33: 46364 | M33: D | S33: Major | Y33: 85 | AB33: =C33&"_"&TEXT(D33,"0#") -> 1956_02
A34: Lisbon Antigua | B34: Nelson Riddle | C34: 1956 | D34: 3 | E34: Pop | F34: N/A | G34: Easy listening | H34: N/A | I34: N/A | J34: https://open.spotify.com/track/07tMKurz0WxXRP7ktP2r8C?si=cc7e3a47ab7c405b | K34: 46116 | M34: C | N34: F | O34: C# | S34: Major | T34: Major | U34: Major | Y34: 80 | AB34: =C34&"_"&TEXT(D34,"0#") -> 1956_03
A35: My Prayer | B35: The Platters | C35: 1956 | D35: 4 | E35: R&B | F35: Pop | G35: Doo-wop | H35: Traditional pop | I35: N/A | J35: https://open.spotify.com/track/1ntGJDSakqsaw1KhptKrB5?si=148cdbd8a3e34558 | K35: 46181 | M35: Bb | S35: Major | Y35: 109 | AB35: =C35&"_"&TEXT(D35,"0#") -> 1956_04
A36: The Wayward Wind | B36: Gogi Grant | C36: 1956 | D36: 5 | E36: Pop | F36: N/A | G36: Easy listening | H36: N/A | I36: N/A | J36: https://open.spotify.com/track/2VqsUEpRPvgiiBdsBuQrJz?si=cf841c4169f24725 | K36: 46116 | M36: Bb | N36: B | S36: Major | T36: Major | Y36: 138 | AB36: =C36&"_"&TEXT(D36,"0#") -> 1956_05
A37: All Shook Up | B37: Elvis Presley | C37: 1957 | D37: 1 | E37: Rock | F37: R&B | G37: N/A | H37: N/A | I37: N/A | J37: https://open.spotify.com/track/5ueyLj6e6oVaTY0KQ6yLaA?si=adde916f9aa04a03 | K37: 46364 | M37: Bb | S37: Major | Y37: 74 | AB37: =C37&"_"&TEXT(D37,"0#") -> 1957_01
A38: Love Letters in the Sand | B38: Pat Boone | C38: 1957 | D38: 2 | E38: Pop | F38: N/A | G38: Traditional pop | H38: N/A | I38: N/A | J38: https://open.spotify.com/track/1eqGYJJr2z2GXK1i0hD3BC?si=821e3dd1c8ca4c4c | K38: 46364 | M38: Eb | S38: Major | Y38: 89 | AB38: =C38&"_"&TEXT(D38,"0#") -> 1957_02
A39: Little Darlin | B39: The Diamonds | C39: 1957 | D39: 3 | E39: R&B | F39: Rock | G39: Doo-wop | H39: N/A | I39: N/A | J39: https://open.spotify.com/track/7ycFNferNuk6wAjBa0vWvl?si=53236816fbc34823 | K39: 46116 | M39: F# | S39: Major | Y39: 153 | AB39: =C39&"_"&TEXT(D39,"0#") -> 1957_03
A40: Young Love | B40: Tab Hunter | C40: 1957 | D40: 4 | E40: Pop | F40: N/A | G40: N/A | H40: N/A | I40: N/A | J40: https://www.youtube.com/watch?v=vm3p1dCSA5Y | K40: 46364 | M40: C | S40: Major | Y40: 102 | AB40: =C40&"_"&TEXT(D40,"0#") -> 1957_04
...
